Workbook

Sheet 1
B1: CKG | C1: MPSG | D1: Resistance | E1: CKG | F1: MPSG | G1: log2(FC) | H1: raw.pval | I1: GENE
A2: OXA-192 | B2: 0 | C2: 74 | D2: penam; cephalosporin | E2: 31.333333 | F2: 13.333333 | G2: 7.2095 | H2: 0.0080072 | I2: geneset000048244 | J2: geneset000052560 | K2: geneset000053176 | L2: geneset000056628 | M2: geneset000064254 | N2: geneset000077996 | O2: geneset000244348 | P2: geneset000250940 | Q2: geneset000254792 | R2: geneset000257926 | S2: geneset000267344 | T2: geneset000276308 | U2: geneset000287062 | V2: geneset000427932 | W2: geneset000432532 | X2: geneset000434199 | Y2: geneset000453950 | Z2: geneset000576881 | AA2: geneset000580311 | AB2: geneset000599853 | AC2: geneset000618296 | AD2: geneset000759409 | AE2: geneset000774645 | AF2: geneset000774805 | AG2: geneset000778412 | AH2: geneset000780842 | AI2: geneset000787254 | AJ2: geneset000793146 | AK2: geneset000797247 | AL2: geneset000925202 | AM2: geneset000941792 | AN2: geneset000951679 | AO2: geneset000964111 | AP2: geneset001099147 | AQ2: geneset001147722 | AR2: geneset001158931 | AS2: geneset001159795 | AT2: geneset001160292 | AU2: geneset001163259 | AV2: geneset001329577 | AW2: geneset001330088 | AX2: geneset001334298 | AY2: geneset001360674 | AZ2: geneset001361421 | BA2: geneset001371566 | BB2: geneset001480421 | BC2: geneset001521510 | BD2: geneset001525989 | BE2: geneset001553918 | BF2: geneset001554454 | BG2: geneset001566399 | BH2: geneset001750913 | BI2: geneset001769803 | BJ2: geneset001775442 | BK2: geneset001936736 | BL2: geneset001938863 | BM2: geneset001942812 | BN2: geneset001947851 | BO2: geneset001953590 | BP2: geneset002127478 | BQ2: geneset002131497 | BR2: geneset002134798 | BS2: geneset002177956 | BT2: geneset002186636 | BU2: geneset002196371 | BV2: geneset002332428 | BW2: geneset002337807 | BX2: geneset002345812 | BY2: geneset002508899 | BZ2: geneset002510439 | CA2: geneset002536869 | CB2: geneset002560863 | CC2: geneset002665318 | CD2: geneset002684713 | CE2: geneset002711282 | CF2: geneset002858005 | CG2: geneset002892624
A3: tetW | B3: 33 | C3: 11.333333 | D3: tetracycline antibiotic | E3: 1616 | F3: 871 | G3: -1.5419 | H3: 0.039823 | I3: geneset000076014 | J3: geneset000263454 | K3: geneset000604224 | L3: geneset000761877 | M3: geneset000895903 | N3: geneset001182843 | O3: geneset001459971 | P3: geneset001958598 | Q3: geneset002091704 | R3: geneset002511458
A4: vanI | B4: 391.66667 | C4: 125.33333 | D4: glycopeptide antibiotic | E4: 639.66667 | F4: 225.66667 | G4: -1.6439 | H4: 0.0054321 | I4: geneset000023509 | J4: geneset000052091 | K4: geneset000182631 | L4: geneset000196490 | M4: geneset000292641 | N4: geneset000302584 | O4: geneset000340955 | P4: geneset000348916 | Q4: geneset000470293 | R4: geneset000713826 | S4: geneset000727689 | T4: geneset000730993 | U4: geneset000740658 | V4: geneset000892979 | W4: geneset001177162 | X4: geneset001231787 | Y4: geneset001237079 | Z4: geneset001268515 | AA4: geneset001292786 | AB4: geneset001378610 | AC4: geneset001506801 | AD4: geneset001513282 | AE4: geneset001780659 | AF4: geneset002004503 | AG4: geneset002290800 | AH4: geneset002304113 | AI4: geneset002580666 | AJ4: geneset002904271 | AK4: geneset002946589
A5: SAT-4 | B5: 21.333333 | C5: 6.6666667 | D5: nucleoside antibiotic | E5: 21.333333 | F5: 6.6666667 | G5: -1.6781 | H5: 0.016997 | I5: geneset001461830 | J5: geneset002327557 | K5: geneset002469584
A6: patA | B6: 95.333333 | C6: 28.333333 | D6: fluoroquinolone antibiotic | E6: 133.66667 | F6: 47 | G6: -1.7505 | H6: 0.030291 | I6: geneset000597528 | J6: geneset001645370
A7: APH(3')-IIIa | B7: 25 | C7: 7.3333333 | D7: aminoglycoside antibiotic | E7: 228.66667 | F7: 135.33333 | G7: -1.7694 | H7: 0.015391 | I7: geneset000802700 | J7: geneset001999369 | K7: geneset002469585 | L7: geneset002528123 | M7: geneset002711308
A8: srmB | B8: 2.3333333 | C8: 0 | D8: macrolide antibiotic | E8: 56.666667 | F8: 52 | G8: -2.2224 | H8: 0.0078198 | I8: geneset000055604 | J8: geneset001365294 | K8: geneset001470242 | L8: geneset002362488 | M8: geneset002412830 | N8: geneset002426881
A9: CrpP | B9: 2.3333333 | C9: 0 | D9: fluoroquinolone antibiotic | E9: 133.66667 | F9: 47 | G9: -2.2224 | H9: 0.0078198 | I9: geneset000487990
A10: CAU-1 | B10: 5.3333333 | C10: 0.66666667 | D10: carbapenem; penam | E10: 69 | F10: 83.666667 | G10: -2.415 | H10: 0.038461 | I10: geneset000010025
A11: Listeria monocytogenes mprF | B11: 4 | C11: 0.33333333 | D11: peptide antibiotic | E11: 49.333333 | F11: 54.666667 | G11: -2.585 | H11: 0.0045624 | I11: geneset000083827 | J11: geneset000425801 | K11: geneset000584519 | L11: geneset000931998 | M11: geneset000942045 | N11: geneset001044074 | O11: geneset001301002 | P11: geneset001368091 | Q11: geneset001569281 | R11: geneset001638141 | S11: geneset001753401 | T11: geneset001763989 | U11: geneset001979177 | V11: geneset002554325 | W11: geneset002694251
A12: rphA | B12: 3.3333333 | C12: 0 | D12: rifamycin antibiotic | E12: 4.6666667 | F12: 0 | G12: -2.737 | H12: 0.041093 | I12: geneset000254700 | J12: geneset000991265 | K12: geneset001327704 | L12: geneset001572765 | M12: geneset001573239 | N12: geneset002132355 | O12: geneset002207301 | P12: geneset002334014 | Q12: geneset002419180 | R12: geneset002451078 | S12: geneset002607591
A13: cipA | B13: 4 | C13: 0 | D13: lincosamide antibiotic; pleuromutilin antibiotic; macrolide antibiotic; oxazolidinone antibiotic; streptogramin antibiotic; phenicol antibiotic | E13: 20.333333 | F13: 23.666667 | G13: -3 | H13: 0.025218 | I13: geneset000164254 | J13: geneset000785138 | K13: geneset001056527 | L13: geneset001137433 | M13: geneset001357105 | N13: geneset001585427 | O13: geneset002244130 | P13: geneset002586101 | Q13: geneset002872552
A14: clbB | B14: 15.666667 | C14: 1.3333333 | D14: lincosamide antibiotic; pleuromutilin antibiotic; macrolide antibiotic; oxazolidinone antibiotic; streptogramin antibiotic; phenicol antibiotic | E14: 20.333333 | F14: 23.666667 | G14: -3.2327 | H14: 0.042778 | I14: geneset000075186 | J14: geneset001090838 | K14: geneset001335135 | L14: geneset001972127 | M14: geneset002606064
A15: rmtH | B15: 36 | C15: 2.6666667 | D15: aminoglycoside antibiotic | E15: 228.66667 | F15: 135.33333 | G15: -3.6674 | H15: 0.038635 | I15: geneset000455120 | J15: geneset000940329 | K15: geneset001006567 | L15: geneset001152608
A16: pp-flo | B16: 7 | C16: 0 | D16: phenicol antibiotic | E16: 75 | F16: 9.3333333 | G16: -3.8074 | H16: 0.036734 | I16: geneset000256558 | J16: geneset000470980 | K16: geneset000520075 | L16: geneset000872072 | M16: geneset000956845 | N16: geneset001321632 | O16: geneset001751566
A17: bcrA | B17: 10 | C17: 0 | D17: peptide antibiotic | E17: 49.333333 | F17: 54.666667 | G17: -4.3219 | H17: 0.0024128 | I17: geneset000340352 | J17: geneset001889704 | K17: geneset002973616
A18: LRA-3 | B18: 20.666667 | C18: 0.66666667 | D18: penam; cephalosporin | E18: 31.333333 | F18: 13.333333 | G18: -4.3692 | H18: 0.0097299 | I18: geneset000036026 | J18: geneset001850063 | K18: geneset002516279 | L18: geneset002547284 | M18: geneset002687387 | N18: geneset002706466 | O18: geneset002770933
A19: adeB | B19: 11 | C19: 0 | D19: glycylcycline; tetracycline antibiotic | E19: 639.66667 | F19: 225.66667 | G19: -4.4594 | H19: 0.0095629 | I19: geneset000611191 | J19: geneset001236080 | K19: geneset001581974 | L19: geneset001741982 | M19: geneset001815171 | N19: geneset002164063 | O19: geneset002201462 | P19: geneset002212951 | Q19: geneset002919613
A20: sul3 | B20: 12 | C20: 0 | D20: sulfone antibiotic; sulfonamide antibiotic | E20: 0 | F20: 0.66666667 | G20: -4.585 | H20: 0.0040843 | I20: geneset001414265 | J20: geneset001970490
A21: Pseudomonas aeruginosa catB6 | B21: 46 | C21: 1.3333333 | D21: phenicol antibiotic | E21: 75 | F21: 9.3333333 | G21: -4.7866 | H21: 0.033758 | I21: geneset000248835 | J21: geneset001189925 | K21: geneset001732186
A22: Bifidobacterium ileS conferring resistance to mupirocin | B22: 15 | C22: 0 | D22: mupirocin | E22: 23 | F22: 3.3333333 | G22: -4.9069 | H22: 0.0059395 | I22: geneset000762526 | J22: geneset000943253 | K22: geneset001194535 | L22: geneset001340919 | M22: geneset001436777 | N22: geneset001540395 | O22: geneset001661645 | P22: geneset001776253 | Q22: geneset002014603 | R22: geneset002574805
A23: TEM-123 | B23: 23.666667 | C23: 0 | D23: penam; penem; cephalosporin; monobactam | E23: 31.333333 | F23: 13.333333 | G23: -5.5648 | H23: 0.0098612 | I23: geneset001604526 | J23: geneset001975958 | K23: geneset002912281

Sheet 2
B1: CK | C1: NPs | D1: Resistance | E1: CK | F1: NPs | G1: log2(FC) | H1: raw.pval | I1: GENE
A2: OXA-192 | B2: 0 | C2: 74 | D2: penam; cephalosporin | E2: 31.333333 | F2: 13.333333 | G2: 7.2095 | H2: 0.0080072 | I2: geneset000048244 | J2: #N/A
A3: OXA-192 | B3: 0 | C3: 74 | D3: penam; cephalosporin | E3: 31.333333 | F3: 13.333333 | G3: 7.2095 | H3: 0.0080072 | I3: geneset000052560 | J3: #N/A
A4: OXA-192 | B4: 0 | C4: 74 | D4: penam; cephalosporin | E4: 31.333333 | F4: 13.333333 | G4: 7.2095 | H4: 0.0080072 | I4: geneset000053176 | J4: #N/A
A5: OXA-192 | B5: 0 | C5: 74 | D5: penam; cephalosporin | E5: 31.333333 | F5: 13.333333 | G5: 7.2095 | H5: 0.0080072 | I5: geneset000056628 | J5: #N/A
A6: OXA-192 | B6: 0 | C6: 74 | D6: penam; cephalosporin | E6: 31.333333 | F6: 13.333333 | G6: 7.2095 | H6: 0.0080072 | I6: geneset000064254 | J6: #N/A
A7: OXA-192 | B7: 0 | C7: 74 | D7: penam; cephalosporin | E7: 31.333333 | F7: 13.333333 | G7: 7.2095 | H7: 0.0080072 | I7: geneset000077996 | J7: #N/A
A8: OXA-192 | B8: 0 | C8: 74 | D8: penam; cephalosporin | E8: 31.333333 | F8: 13.333333 | G8: 7.2095 | H8: 0.0080072 | I8: geneset000244348 | J8: #N/A
A9: OXA-192 | B9: 0 | C9: 74 | D9: penam; cephalosporin | E9: 31.333333 | F9: 13.333333 | G9: 7.2095 | H9: 0.0080072 | I9: geneset000250940 | J9: #N/A
A10: OXA-192 | B10: 0 | C10: 74 | D10: penam; cephalosporin | E10: 31.333333 | F10: 13.333333 | G10: 7.2095 | H10: 0.0080072 | I10: geneset000254792 | J10: #N/A
A11: OXA-192 | B11: 0 | C11: 74 | D11: penam; cephalosporin | E11: 31.333333 | F11: 13.333333 | G11: 7.2095 | H11: 0.0080072 | I11: geneset000257926 | J11: #N/A
A12: OXA-192 | B12: 0 | C12: 74 | D12: penam; cephalosporin | E12: 31.333333 | F12: 13.333333 | G12: 7.2095 | H12: 0.0080072 | I12: geneset000267344 | J12: #N/A
A13: OXA-192 | B13: 0 | C13: 74 | D13: penam; cephalosporin | E13: 31.333333 | F13: 13.333333 | G13: 7.2095 | H13: 0.0080072 | I13: geneset000276308 | J13: #N/A
... A41: OXA-192 | B41: 0 | C41: 74 | D41: penam; cephalosporin | E41: 31.333333 | F41: 13.333333 | G41: 7.2095 | H41: 0.0080072 | I41: geneset001329577 | J41: #N/A
A42: OXA-192 | B42: 0 | C42: 74 | D42: penam; cephalosporin | E42: 31.333333 | F42: 13.333333 | G42: 7.2095 | H42: 0.0080072 | I42: geneset001330088 | J42: k__Bacteria; p__Chlamydiae; c__Chlamydiia; o__Chlamydiales; f__Chlamydiaceae; g__Chlamydia; s__Unclassified
A43: OXA-192 | B43: 0 | C43: 74 | D43: penam; cephalosporin | E43: 31.333333 | F43: 13.333333 | G43: 7.2095 | H43: 0.0080072 | I43: geneset001334298 | J43: #N/A
A44: OXA-192 | B44: 0 | C44: 74 | D44: penam; cephalosporin | E44: 31.333333 | F44: 13.333333 | G44: 7.2095 | H44: 0.0080072 | I44: geneset001360674 | J44: #N/A
A45: OXA-192 | B45: 0 | C45: 74 | D45: penam; cephalosporin | E45: 31.333333 | F45: 13.333333 | G45: 7.2095 | H45: 0.0080072 | I45: geneset001361421 | J45: #N/A
A46: OXA-192 | B46: 0 | C46: 74 | D46: penam; cephalosporin | E46: 31.333333 | F46: 13.333333 | G46: 7.2095 | H46: 0.0080072 | I46: geneset001371566 | J46: #N/A
A47: OXA-192 | B47: 0 | C47: 74 | D47: penam; cephalosporin | E47: 31.333333 | F47: 13.333333 | G47: 7.2095 | H47: 0.0080072 | I47: geneset001480421 | J47: #N/A
A48: OXA-192 | B48: 0 | C48: 74 | D48: penam; cephalosporin | E48: 31.333333 | F48: 13.333333 | G48: 7.2095 | H48: 0.0080072 | I48: geneset001521510 | J48: #N/A
A49: OXA-192 | B49: 0 | C49: 74 | D49: penam; cephalosporin | E49: 31.333333 | F49: 13.333333 | G49: 7.2095 | H49: 0.0080072 | I49: geneset001525989 | J49: #N/A
A50: OXA-192 | B50: 0 | C50: 74 | D50: penam; cephalosporin | E50: 31.333333 | F50: 13.333333 | G50: 7.2095 | H50: 0.0080072 | I50: geneset001553918 | J50: k__Bacteria; p__Chlamydiae; c__Chlamydiia; o__Chlamydiales; f__Chlamydiaceae; g__Chlamydia; s__Unclassified
A51: OXA-192 | B51: 0 | C51: 74 | D51: penam; cephalosporin | E51: 31.333333 | F51: 13.333333 | G51: 7.2095 | H51: 0.0080072 | I51: geneset001554454 | J51: #N/A
A52: OXA-192 | B52: 0 | C52: 74 | D52: penam; cephalosporin | E52: 31.333333 | F52: 13.333333 | G52: 7.2095 | H52: 0.0080072 | I52: geneset001566399 | J52: #N/A
A53: OXA-192 | B53: 0 | C53: 74 | D53: penam; cephalosporin | E53: 31.333333 | F53: 13.333333 | G53: 7.2095 | H53: 0.0080072 | I53: geneset001750913 | J53: #N/A
A54: OXA-192 | B54: 0 | C54: 74 | D54: penam; cephalosporin | E54: 31.333333 | F54: 13.333333 | G54: 7.2095 | H54: 0.0080072 | I54: geneset001769803 | J54: #N/A
A55: OXA-192 | B55: 0 | C55: 74 | D55: penam; cephalosporin | E55: 31.333333 | F55: 13.333333 | G55: 7.2095 | H55: 0.0080072 | I55: geneset001775442 | J55: #N/A
A56: OXA-192 | B56: 0 | C56: 74 | D56: penam; cephalosporin | E56: 31.333333 | F56: 13.333333 | G56: 7.2095 | H56: 0.0080072 | I56: geneset001936736 | J56: #N/A
A57: OXA-192 | B57: 0 | C57: 74 | D57: penam; cephalosporin | E57: 31.333333 | F57: 13.333333 | G57: 7.2095 | H57: 0.0080072 | I57: geneset001938863 | J57: #N/A
A58: OXA-192 | B58: 0 | C58: 74 | D58: penam; cephalosporin | E58: 31.333333 | F58: 13.333333 | G58: 7.2095 | H58: 0.0080072 | I58: geneset001942812 | J58: #N/A
A59: OXA-192 | B59: 0 | C59: 74 | D59: penam; cephalosporin | E59: 31.333333 | F59: 13.333333 | G59: 7.2095 | H59: 0.0080072 | I59: geneset001947851 | J59: #N/A
A60: OXA-192 | B60: 0 | C60: 74 | D60: penam; cephalosporin | E60: 31.333333 | F60: 13.333333 | G60: 7.2095 | H60: 0.0080072 | I60: geneset001953590 | J60: #N/A
A61: OXA-192 | B61: 0 | C61: 74 | D61: penam; cephalosporin | E61: 31.333333 | F61: 13.333333 | G61: 7.2095 | H61: 0.0080072 | I61: geneset002127478 | J61: #N/A
A62: OXA-192 | B62: 0 | C62: 74 | D62: penam; cephalosporin | E62: 31.333333 | F62: 13.333333 | G62: 7.2095 | H62: 0.0080072 | I62: geneset002131497 | J62: #N/A
... A82: tetW | B82: 33 | C82: 11.333333 | D82: tetracycline antibiotic | E82: 1616 | F82: 871 | G82: -1.5419 | H82: 0.039823 | I82: geneset000761877 | J82: #N/A
A83: tetW | B83: 33 | C83: 11.333333 | D83: tetracycline antibiotic | E83: 1616 | F83: 871 | G83: -1.5419 | H83: 0.039823 | I83: geneset000895903 | J83: k__Bacteria; p__Firmicutes; c__Clostridia; o__Clostridiales; f__Ruminococcaceae; g__Unclassified; s__Unclassified
A84: tetW | B84: 33 | C84: 11.333333 | D84: tetracycline antibiotic | E84: 1616 | F84: 871 | G84: -1.5419 | H84: 0.039823 | I84: geneset001182843 | J84: k__Bacteria; p__Actinobacteria; c__Actinobacteria; o__Bifidobacteriales; f__Bifidobacteriaceae; g__Bifidobacterium; s__Bifidobacterium_pullorum
A85: tetW | B85: 33 | C85: 11.333333 | D85: tetracycline antibiotic | E85: 1616 | F85: 871 | G85: -1.5419 | H85: 0.039823 | I85: geneset001459971 | J85: k__Bacteria; p__Firmicutes; c__Clostridia; o__Clostridiales; f__Clostridiaceae; g__Clostridium; s__Unclassified
A86: tetW | B86: 33 | C86: 11.333333 | D86: tetracycline antibiotic | E86: 1616 | F86: 871 | G86: -1.5419 | H86: 0.039823 | I86: geneset001958598 | J86: #N/A
...

Sheet 3
B1: CK | C1: NPs | D1: Resistance | E1: CK | F1: NPs | G1: log2(FC) | H1: raw.pval | I1: GENE | J1: CK | K1: NPs | R1: S | S1: CK1 | T1: CK2 | U1: CK3 | V1: NPs1 | W1: NPs2 | X1: NPs3
A2: OXA-192 | B2: 0 | C2: 74 | D2: penam; cephalosporin | E2: 31.333333 | F2: 13.333333 | G2: 7.2095 | H2: 0.0080072 | I2: geneset001330088 | J2: 19674.333 | K2: 67968.667 | L2: k__Bacteria | M2: p__Chlamydiae | N2: c__Chlamydiia | O2: o__Chlamydiales | P2: f__Chlamydiaceae | Q2: g__Chlamydia | R2: s__Unclassified
A3: OXA-192 | B3: 0 | C3: 74 | D3: penam; cephalosporin | E3: 31.333333 | F3: 13.333333 | G3: 7.2095 | H3: 0.0080072 | I3: geneset001553918 | J3: 19674.333 | K3: 67968.667 | L3: k__Bacteria | M3: p__Chlamydiae | N3: c__Chlamydiia | O3: o__Chlamydiales | P3: f__Chlamydiaceae | Q3: g__Chlamydia | R3: s__Unclassified
A4: tetW | B4: 33 | C4: 11.333333 | D4: tetracycline antibiotic | E4: 1616 | F4: 871 | G4: -1.5419 | H4: 0.039823 | I4: geneset000895903 | J4: 31252.667 | K4: 13068.667 | L4: k__Bacteria | M4: p__Firmicutes | N4: c__Clostridia | O4: o__Clostridiales | P4: f__Ruminococcaceae | Q4: g__Unclassified | R4: s__Unclassified
A5: tetW | B5: 33 | C5: 11.333333 | D5: tetracycline antibiotic | E5: 1616 | F5: 871 | G5: -1.5419 | H5: 0.039823 | I5: geneset001182843 | J5: 46.333333 | K5: 22.666667 | L5: k__Bacteria | M5: p__Actinobacteria | N5: c__Actinobacteria | O5: o__Bifidobacteriales | P5: f__Bifidobacteriaceae | Q5: g__Bifidobacterium | R5: s__Bifidobacterium_pullorum | S5: 75 | T5: 25 | U5: 39 | V5: 20 | W5: 26 | X5: 22
A6: tetW | B6: 33 | C6: 11.333333 | D6: tetracycline antibiotic | E6: 1616 | F6: 871 | G6: -1.5419 | H6: 0.039823 | I6: geneset001459971 | J6: 49344.667 | K6: 27215.333 | L6: k__Bacteria | M6: p__Firmicutes | N6: c__Clostridia | O6: o__Clostridiales | P6: f__Clostridiaceae | Q6: g__Clostridium | R6: s__Unclassified | S6: 52202 | T6: 17847 | U6: 63068 | V6: 16683 | W6: 11562 | X6: 12785
A7: vanI | B7: 391.66667 | C7: 125.33333 | D7: glycopeptide antibiotic | E7: 639.66667 | F7: 225.66667 | G7: -1.6439 | H7: 0.0054321 | I7: geneset000023509 | J7: 167625.33 | K7: 75814 | L7: k__Bacteria | M7: p__Firmicutes | N7: c__Unclassified | O7: o__Unclassified | P7: f__Unclassified | Q7: g__Unclassified | R7: s__Unclassified | S7: 311942 | T7: 33439 | U7: 98291 | V7: 141701 | W7: 21928 | X7: 100156
A8: vanI | B8: 391.66667 | C8: 125.33333 | D8: glycopeptide antibiotic | E8: 639.66667 | F8: 225.66667 | G8: -1.6439 | H8: 0.0054321 | I8: geneset000182631 | J8: 44372.333 | K8: 13676.667 | L8: k__Bacteria | M8: p__Firmicutes | N8: c__Clostridia | O8: o__Clostridiales | P8: f__Eubacteriaceae | Q8: g__Eubacterium | R8: s__Eubacterium_sp._14-2 | S8: 311942 | T8: 33439 | U8: 98291 | V8: 141701 | W8: 21928 | X8: 100156
A9: vanI | B9: 391.66667 | C9: 125.33333 | D9: glycopeptide antibiotic | E9: 639.66667 | F9: 225.66667 | G9: -1.6439 | H9: 0.0054321 | I9: geneset000196490 | J9: 147890.67 | K9: 87928.333 | L9: k__Bacteria | M9: p__Firmicutes | N9: c__Clostridia | O9: o__Clostridiales | P9: f__Lachnospiraceae | Q9: g__Unclassified | R9: s__Lachnospiraceae_bacterium_3-1 | S9: 44709 | T9: 65337 | U9: 32968 | V9: 10819 | W9: 19497 | X9: 10245
A10: vanI | B10: 391.66667 | C10: 125.33333 | D10: glycopeptide antibiotic | E10: 639.66667 | F10: 225.66667 | G10: -1.6439 | H10: 0.0054321 | I10: geneset000292641 | J10: 147890.67 | K10: 87928.333 | L10: k__Bacteria | M10: p__Firmicutes | N10: c__Clostridia | O10: o__Clostridiales | P10: f__Lachnospiraceae | Q10: g__Unclassified | R10: s__Lachnospiraceae_bacterium_3-1 | S10: 63667 | T10: 51260 | U10: 71284 | V10: 11536 | W10: 25880 | X10: 12271
A11: vanI | B11: 391.66667 | C11: 125.33333 | D11: glycopeptide antibiotic | E11: 639.66667 | F11: 225.66667 | G11: -1.6439 | H11: 0.0054321 | I11: geneset000302584 | J11: 47671.333 | K11: 13520.333 | L11: k__Bacteria | M11: p__Firmicutes | N11: c__Clostridia | O11: o__Clostridiales | P11: f__Clostridiaceae | Q11: g__Clostridium | R11: s__uncultured_Clostridium_sp. | S11: 33110 | T11: 71724 | U11: 25479 | V11: 7493 | W11: 15728 | X11: 7432
A12: vanI | B12: 391.66667 | C12: 125.33333 | D12: glycopeptide antibiotic | E12: 639.66667 | F12: 225.66667 | G12: -1.6439 | H12: 0.0054321 | I12: geneset000340955 | J12: 858517.67 | K12: 494857.67 | L12: k__Bacteria | M12: p__Unclassified | N12: c__Unclassified | O12: o__Unclassified | P12: f__Unclassified | Q12: g__Unclassified | R12: s__Unclassified | S12: 131071 | T12: 91643 | U12: 112318 | V12: 28737 | W12: 41922 | X12: 30886
A13: vanI | B13: 391.66667 | C13: 125.33333 | D13: glycopeptide antibiotic | E13: 639.66667 | F13: 225.66667 | G13: -1.6439 | H13: 0.0054321 | I13: geneset000348916 | J13: 167625.33 | K13: 75814 | L13: k__Bacteria | M13: p__Firmicutes | N13: c__Unclassified | O13: o__Unclassified | P13: f__Unclassified | Q13: g__Unclassified | R13: s__Unclassified | S13: 115697 | T13: 85831 | U13: 102929 | V13: 24281 | W13: 50643 | X13: 35917
A14: vanI | B14: 391.66667 | C14: 125.33333 | D14: glycopeptide antibiotic | E14: 639.66667 | F14: 225.66667 | G14: -1.6439 | H14: 0.0054321 | I14: geneset000470293 | J14: 62070.333 | K14: 16562.333 | L14: k__Bacteria | M14: p__Unclassified | N14: c__Unclassified | O14: o__Unclassified | P14: f__Unclassified | Q14: g__Unclassified | R14: s__bacterium_0.1xD8-82 | S14: 7482 | T14: 949 | U14: 1137 | V14: 442 | W14: 9406 | X14: 249
A15: vanI | B15: 391.66667 | C15: 125.33333 | D15: glycopeptide antibiotic | E15: 639.66667 | F15: 225.66667 | G15: -1.6439 | H15: 0.0054321 | I15: geneset000713826 | J15: 43437.667 | K15: 10217.667 | L15: k__Bacteria | M15: p__Firmicutes | N15: c__Clostridia | O15: o__Clostridiales | P15: f__Lachnospiraceae | Q15: g__Lachnoclostridium | R15: s__Lachnoclostridium_sp._An138 | S15: 63667 | T15: 51260 | U15: 71284 | V15: 11536 | W15: 25880 | X15: 12271
A16: vanI | B16: 391.66667 | C16: 125.33333 | D16: glycopeptide antibiotic | E16: 639.66667 | F16: 225.66667 | G16: -1.6439 | H16: 0.0054321 | I16: geneset000727689 | J16: 111677.33 | K16: 33848.333 | L16: k__Bacteria | M16: p__Unclassified | N16: c__Unclassified | O16: o__Unclassified | P16: f__Unclassified | Q16: g__Unclassified | R16: s__bacterium_1xD42-67 | S16: 64890 | T16: 61298 | U16: 63082 | V16: 15587 | W16: 59600 | X16: 14788
... A31: CrpP | B31: 2.3333333 | C31: 0 | D31: fluoroquinolone antibiotic | E31: 133.66667 | F31: 47 | G31: -2.2224 | H31: 0.0078198 | I31: geneset000487990 | J31: 4238.6667 | K31: 1214.6667 | L31: k__Bacteria | M31: p__Firmicutes | N31: c__Clostridia | O31: o__Clostridiales | P31: f__Oscillospiraceae | Q31: g__Unclassified | R31: s__Unclassified | S31: 8265 | T31: 11602 | U31: 8893 | V31: 2453 | W31: 5875 | X31: 1931
A32: Listeria monocytogenes mprF | B32: 4 | C32: 0.33333333 | D32: peptide antibiotic | E32: 49.333333 | F32: 54.666667 | G32: -2.585 | H32: 0.0045624 | I32: geneset001044074 | J32: 123 | K32: 11 | L32: k__Bacteria | M32: p__Proteobacteria | N32: c__Deltaproteobacteria | O32: o__Desulfovibrionales | P32: f__Desulfovibrionaceae | Q32: g__Desulfovibrio | R32: s__Desulfovibrio_africanus | S32: =VLOOKUP($R32,[1]导出筛选结果!$G:$M,MATCH(S$1,[1]导出筛选结果!$G$1:$M$1,0),FALSE) -> #N/A | T32: =VLOOKUP($R32,[1]导出筛选结果!$G:$M,MATCH(T$1,[1]导出筛选结果!$G$1:$M$1,0),FALSE) -> #N/A | U32: =VLOOKUP($R32,[1]导出筛选结果!$G:$M,MATCH(U$1,[1]导出筛选结果!$G$1:$M$1,0),FALSE) -> #N/A | V32: =VLOOKUP($R32,[1]导出筛选结果!$G:$M,MATCH(V$1,[1]导出筛选结果!$G$1:$M$1,0),FALSE) -> #N/A | W32: =VLOOKUP($R32,[1]导出筛选结果!$G:$M,MATCH(W$1,[1]导出筛选结果!$G$1:$M$1,0),FALSE) -> #N/A | X32: =VLOOKUP($R32,[1]导出筛选结果!$G:$M,MATCH(X$1,[1]导出筛选结果!$G$1:$M$1,0),FALSE) -> #N/A
A33: Listeria monocytogenes mprF | B33: 4 | C33: 0.33333333 | D33: peptide antibiotic | E33: 49.333333 | F33: 54.666667 | G33: -2.585 | H33: 0.0045624 | I33: geneset001638141 | J33: 62.666667 | K33: 11 | L33: k__Bacteria | M33: p__Firmicutes | N33: c__Bacilli | O33: o__Bacillales | P33: f__Paenibacillaceae | Q33: g__Paenibacillus | R33: s__Paenibacillus_kribbensis | S33: =VLOOKUP($R33,[1]导出筛选结果!$G:$M,MATCH(S$1,[1]导出筛选结果!$G$1:$M$1,0),FALSE) -> #N/A | T33: =VLOOKUP($R33,[1]导出筛选结果!$G:$M,MATCH(T$1,[1]导出筛选结果!$G$1:$M$1,0),FALSE) -> #N/A | U33: =VLOOKUP($R33,[1]导出筛选结果!$G:$M,MATCH(U$1,[1]导出筛选结果!$G$1:$M$1,0),FALSE) -> #N/A | V33: =VLOOKUP($R33,[1]导出筛选结果!$G:$M,MATCH(V$1,[1]导出筛选结果!$G$1:$M$1,0),FALSE) -> #N/A | W33: =VLOOKUP($R33,[1]导出筛选结果!$G:$M,MATCH(W$1,[1]导出筛选结果!$G$1:$M$1,0),FALSE) -> #N/A | X33: =VLOOKUP($R33,[1]导出筛选结果!$G:$M,MATCH(X$1,[1]导出筛选结果!$G$1:$M$1,0),FALSE) -> #N/A
A34: cipA | B34: 4 | C34: 0 | D34: lincosamide antibiotic; pleuromutilin antibiotic; macrolide antibiotic; oxazolidinone antibiotic; streptogramin antibiotic; phenicol antibiotic | E34: 20.333333 | F34: 23.666667 | G34: -3 | H34: 0.025218 | I34: geneset001056527 | J34: 63845.333 | K34: 17431.333 | L34: k__Bacteria | M34: p__Firmicutes | N34: c__Clostridia | O34: o__Clostridiales | P34: f__Eubacteriaceae | Q34: g__Eubacterium | R34: s__Eubacterium_plexicaudatum | S34: =VLOOKUP($R34,[1]导出筛选结果!$G:$M,MATCH(S$1,[1]导出筛选结果!$G$1:$M$1,0),FALSE) -> #N/A | T34: =VLOOKUP($R34,[1]导出筛选结果!$G:$M,MATCH(T$1,[1]导出筛选结果!$G$1:$M$1,0),FALSE) -> #N/A | U34: =VLOOKUP($R34,[1]导出筛选结果!$G:$M,MATCH(U$1,[1]导出筛选结果!$G$1:$M$1,0),FALSE) -> #N/A | V34: =VLOOKUP($R34,[1]导出筛选结果!$G:$M,MATCH(V$1,[1]导出筛选结果!$G$1:$M$1,0),FALSE) -> #N/A | W34: =VLOOKUP($R34,[1]导出筛选结果!$G:$M,MATCH(W$1,[1]导出筛选结果!$G$1:$M$1,0),FALSE) -> #N/A | X34: =VLOOKUP($R34,[1]导出筛选结果!$G:$M,MATCH(X$1,[1]导出筛选结果!$G$1:$M$1,0),FALSE) -> #N/A
A35: cipA | B35: 4 | C35: 0 | D35: lincosamide antibiotic; pleuromutilin antibiotic; macrolide antibiotic; oxazolidinone antibiotic; streptogramin antibiotic; phenicol antibiotic | E35: 20.333333 | F35: 23.666667 | G35: -3 | H35: 0.025218 | I35: geneset001585427 | J35: 146821.33 | K35: 261782.67 | L35: k__Bacteria | M35: p__Bacteroidetes | N35: c__Bacteroidia | O35: o__Bacteroidales | P35: f__Muribaculaceae | Q35: g__Unclassified | R35: s__Unclassified
A36: clbB | B36: 15.666667 | C36: 1.3333333 | D36: lincosamide antibiotic; pleuromutilin antibiotic; macrolide antibiotic; oxazolidinone antibiotic; streptogramin antibiotic; phenicol antibiotic | E36: 20.333333 | F36: 23.666667 | G36: -3.2327 | H36: 0.042778 | I36: geneset001090838 | J36: 22 | K36: 18 | L36: k__Bacteria | M36: p__Firmicutes | N36: c__Clostridia | O36: o__Clostridiales | P36: f__Clostridiaceae | Q36: g__Clostridium | R36: s__Clostridium_algidicarnis | S36: =VLOOKUP($R36,[1]导出筛选结果!$G:$M,MATCH(S$1,[1]导出筛选结果!$G$1:$M$1,0),FALSE) -> #N/A | T36: =VLOOKUP($R36,[1]导出筛选结果!$G:$M,MATCH(T$1,[1]导出筛选结果!$G$1:$M$1,0),FALSE) -> #N/A | U36: =VLOOKUP($R36,[1]导出筛选结果!$G:$M,MATCH(U$1,[1]导出筛选结果!$G$1:$M$1,0),FALSE) -> #N/A | V36: =VLOOKUP($R36,[1]导出筛选结果!$G:$M,MATCH(V$1,[1]导出筛选结果!$G$1:$M$1,0),FALSE) -> #N/A | W36: =VLOOKUP($R36,[1]导出筛选结果!$G:$M,MATCH(W$1,[1]导出筛选结果!$G$1:$M$1,0),FALSE) -> #N/A | X36: =VLOOKUP($R36,[1]导出筛选结果!$G:$M,MATCH(X$1,[1]导出筛选结果!$G$1:$M$1,0),FALSE) -> #N/A
A37: rmtH | B37: 36 | C37: 2.6666667 | D37: aminoglycoside antibiotic | E37: 228.66667 | F37: 135.33333 | G37: -3.6674 | H37: 0.038635 | I37: geneset001006567 | J37: 14720.333 | K37: 5963 | L37: k__Bacteria | M37: p__Proteobacteria | N37: c__Deltaproteobacteria | O37: o__Desulfovibrionales | P37: f__Desulfovibrionaceae | Q37: g__Desulfovibrio | R37: s__Unclassified
A38: pp-flo | B38: 7 | C38: 0 | D38: phenicol antibiotic | E38: 75 | F38: 9.3333333 | G38: -3.8074 | H38: 0.036734 | I38: geneset000470980 | J38: 158596.33 | K38: 43682.667 | L38: k__Bacteria | M38: p__Firmicutes | N38: c__Clostridia | O38: o__Clostridiales | P38: f__Oscillospiraceae | Q38: g__Oscillibacter | R38: s__Oscillibacter_sp._1-3 | S38: =VLOOKUP($R38,[1]导出筛选结果!$G:$M,MATCH(S$1,[1]导出筛选结果!$G$1:$M$1,0),FALSE) -> #N/A | T38: =VLOOKUP($R38,[1]导出筛选结果!$G:$M,MATCH(T$1,[1]导出筛选结果!$G$1:$M$1,0),FALSE) -> #N/A | U38: =VLOOKUP($R38,[1]导出筛选结果!$G:$M,MATCH(U$1,[1]导出筛选结果!$G$1:$M$1,0),FALSE) -> #N/A | V38: =VLOOKUP($R38,[1]导出筛选结果!$G:$M,MATCH(V$1,[1]导出筛选结果!$G$1:$M$1,0),FALSE) -> #N/A | W38: =VLOOKUP($R38,[1]导出筛选结果!$G:$M,MATCH(W$1,[1]导出筛选结果!$G$1:$M$1,0),FALSE) -> #N/A | X38: =VLOOKUP($R38,[1]导出筛选结果!$G:$M,MATCH(X$1,[1]导出筛选结果!$G$1:$M$1,0),FALSE) -> #N/A
A39: pp-flo | B39: 7 | C39: 0 | D39: phenicol antibiotic | E39: 75 | F39: 9.3333333 | G39: -3.8074 | H39: 0.036734 | I39: geneset000520075 | J39: 68419 | K39: 22090.667 | L39: k__Bacteria | M39: p__Firmicutes | N39: c__Clostridia | O39: o__Clostridiales | P39: f__Clostridiaceae | Q39: g__Butyricicoccus | R39: s__Butyricicoccus_sp._1XD8-22 | S39: =VLOOKUP($R39,[1]导出筛选结果!$G:$M,MATCH(S$1,[1]导出筛选结果!$G$1:$M$1,0),FALSE) -> #N/A | T39: =VLOOKUP($R39,[1]导出筛选结果!$G:$M,MATCH(T$1,[1]导出筛选结果!$G$1:$M$1,0),FALSE) -> #N/A | U39: =VLOOKUP($R39,[1]导出筛选结果!$G:$M,MATCH(U$1,[1]导出筛选结果!$G$1:$M$1,0),FALSE) -> #N/A | V39: =VLOOKUP($R39,[1]导出筛选结果!$G:$M,MATCH(V$1,[1]导出筛选结果!$G$1:$M$1,0),FALSE) -> #N/A | W39: =VLOOKUP($R39,[1]导出筛选结果!$G:$M,MATCH(W$1,[1]导出筛选结果!$G$1:$M$1,0),FALSE) -> #N/A | X39: =VLOOKUP($R39,[1]导出筛选结果!$G:$M,MATCH(X$1,[1]导出筛选结果!$G$1:$M$1,0),FALSE) -> #N/A
A40: pp-flo | B40: 7 | C40: 0 | D40: phenicol antibiotic | E40: 75 | F40: 9.3333333 | G40: -3.8074 | H40: 0.036734 | I40: geneset000872072 | J40: 68419 | K40: 22090.667 | L40: k__Bacteria | M40: p__Firmicutes | N40: c__Clostridia | O40: o__Clostridiales | P40: f__Clostridiaceae | Q40: g__Butyricicoccus | R40: s__Butyricicoccus_sp._1XD8-22 | S40: =VLOOKUP($R40,[1]导出筛选结果!$G:$M,MATCH(S$1,[1]导出筛选结果!$G$1:$M$1,0),FALSE) -> #N/A | T40: =VLOOKUP($R40,[1]导出筛选结果!$G:$M,MATCH(T$1,[1]导出筛选结果!$G$1:$M$1,0),FALSE) -> #N/A | U40: =VLOOKUP($R40,[1]导出筛选结果!$G:$M,MATCH(U$1,[1]导出筛选结果!$G$1:$M$1,0),FALSE) -> #N/A | V40: =VLOOKUP($R40,[1]导出筛选结果!$G:$M,MATCH(V$1,[1]导出筛选结果!$G$1:$M$1,0),FALSE) -> #N/A | W40: =VLOOKUP($R40,[1]导出筛选结果!$G:$M,MATCH(W$1,[1]导出筛选结果!$G$1:$M$1,0),FALSE) -> #N/A | X40: =VLOOKUP($R40,[1]导出筛选结果!$G:$M,MATCH(X$1,[1]导出筛选结果!$G$1:$M$1,0),FALSE) -> #N/A
A41: bcrA | B41: 10 | C41: 0 | D41: peptide antibiotic | E41: 49.333333 | F41: 54.666667 | G41: -4.3219 | H41: 0.0024128 | I41: geneset000340352 | J41: 9586.6667 | K41: 3419.6667 | L41: k__Bacteria | M41: p__Firmicutes | N41: c__Clostridia | O41: o__Clostridiales | P41: f__Lachnospiraceae | Q41: g__Roseburia | R41: s__Roseburia_intestinalis | S41: =VLOOKUP($R41,[1]导出筛选结果!$G:$M,MATCH(S$1,[1]导出筛选结果!$G$1:$M$1,0),FALSE) -> #N/A | T41: =VLOOKUP($R41,[1]导出筛选结果!$G:$M,MATCH(T$1,[1]导出筛选结果!$G$1:$M$1,0),FALSE) -> #N/A | U41: =VLOOKUP($R41,[1]导出筛选结果!$G:$M,MATCH(U$1,[1]导出筛选结果!$G$1:$M$1,0),FALSE) -> #N/A | V41: =VLOOKUP($R41,[1]导出筛选结果!$G:$M,MATCH(V$1,[1]导出筛选结果!$G$1:$M$1,0),FALSE) -> #N/A | W41: =VLOOKUP($R41,[1]导出筛选结果!$G:$M,MATCH(W$1,[1]导出筛选结果!$G$1:$M$1,0),FALSE) -> #N/A | X41: =VLOOKUP($R41,[1]导出筛选结果!$G:$M,MATCH(X$1,[1]导出筛选结果!$G$1:$M$1,0),FALSE) -> #N/A
A42: sul3 | B42: 12 | C42: 0 | D42: sulfone antibiotic; sulfonamide antibiotic | E42: 0 | F42: 0.66666667 | G42: -4.585 | H42: 0.0040843 | I42: geneset001414265 | J42: 858517.67 | K42: 494857.67 | L42: k__Bacteria | M42: p__Unclassified | N42: c__Unclassified | O42: o__Unclassified | P42: f__Unclassified | Q42: g__Unclassified | R42: s__Unclassified
A43: TEM-123 | B43: 23.666667 | C43: 0 | D43: penam; penem; cephalosporin; monobactam | E43: 31.333333 | F43: 13.333333 | G43: -5.5648 | H43: 0.0098612 | I43: geneset001604526 | J43: 167625.33 | K43: 75814 | L43: k__Bacteria | M43: p__Firmicutes | N43: c__Unclassified | O43: o__Unclassified | P43: f__Unclassified | Q43: g__Unclassified | R43: s__Unclassified

Sheet 4
B1: CK | C1: NPs | D1: Resistance | E1: CK | F1: NPs | G1: log2(FC) | H1: raw.pval | I1: GENE | J1: CK | K1: NPs | S1: CK1 | T1: CK2 | U1: CK3 | V1: NPs1 | W1: NPs2 | X1: NPs3
A2: tetW | B2: 33 | C2: 11.333333 | D2: tetracycline antibiotic | E2: 1616 | F2: 871 | G2: -1.5419 | H2: 0.039823 | I2: geneset001182843 | J2: 46.333333 | K2: 22.666667 | L2: k__Bacteria | M2: p__Actinobacteria | N2: c__Actinobacteria | O2: o__Bifidobacteriales | P2: f__Bifidobacteriaceae | Q2: g__Bifidobacterium | R2: s__Bifidobacterium_pullorum | S2: 75 | T2: 25 | U2: 39 | V2: 20 | W2: 26 | X2: 22
A3: vanI | B3: 391.66667 | C3: 125.33333 | D3: glycopeptide antibiotic | E3: 639.66667 | F3: 225.66667 | G3: -1.6439 | H3: 0.0054321 | I3: geneset000182631 | J3: 44372.333 | K3: 13676.667 | L3: k__Bacteria | M3: p__Firmicutes | N3: c__Clostridia | O3: o__Clostridiales | P3: f__Eubacteriaceae | Q3: g__Eubacterium | R3: s__Eubacterium_sp._14-2 | S3: 311942 | T3: 33439 | U3: 98291 | V3: 141701 | W3: 21928 | X3: 100156
A4: vanI | B4: 391.66667 | C4: 125.33333 | D4: glycopeptide antibiotic | E4: 639.66667 | F4: 225.66667 | G4: -1.6439 | H4: 0.0054321 | I4: geneset000196490 | J4: 147890.67 | K4: 87928.333 | L4: k__Bacteria | M4: p__Firmicutes | N4: c__Clostridia | O4: o__Clostridiales | P4: f__Lachnospiraceae | Q4: g__Unclassified | R4: s__Lachnospiraceae_bacterium_3-1 | S4: 44709 | T4: 65337 | U4: 32968 | V4: 10819 | W4: 19497 | X4: 10245
A5: vanI | B5: 391.66667 | C5: 125.33333 | D5: glycopeptide antibiotic | E5: 639.66667 | F5: 225.66667 | G5: -1.6439 | H5: 0.0054321 | I5: geneset000292641 | J5: 147890.67 | K5: 87928.333 | L5: k__Bacteria | M5: p__Firmicutes | N5: c__Clostridia | O5: o__Clostridiales | P5: f__Lachnospiraceae | Q5: g__Unclassified | R5: s__Lachnospiraceae_bacterium_3-1 | S5: 63667 | T5: 51260 | U5: 71284 | V5: 11536 | W5: 25880 | X5: 12271
A6: vanI | B6: 391.66667 | C6: 125.33333 | D6: glycopeptide antibiotic | E6: 639.66667 | F6: 225.66667 | G6: -1.6439 | H6: 0.0054321 | I6: geneset000302584 | J6: 47671.333 | K6: 13520.333 | L6: k__Bacteria | M6: p__Firmicutes | N6: c__Clostridia | O6: o__Clostridiales | P6: f__Clostridiaceae | Q6: g__Clostridium | R6: s__uncultured_Clostridium_sp. | S6: 33110 | T6: 71724 | U6: 25479 | V6: 7493 | W6: 15728 | X6: 7432
A7: vanI | B7: 391.66667 | C7: 125.33333 | D7: glycopeptide antibiotic | E7: 639.66667 | F7: 225.66667 | G7: -1.6439 | H7: 0.0054321 | I7: geneset000470293 | J7: 62070.333 | K7: 16562.333 | L7: k__Bacteria | M7: p__Unclassified | N7: c__Unclassified | O7: o__Unclassified | P7: f__Unclassified | Q7: g__Unclassified | R7: s__bacterium_0.1xD8-82 | S7: 7482 | T7: 949 | U7: 1137 | V7: 442 | W7: 9406 | X7: 249
A8: vanI | B8: 391.66667 | C8: 125.33333 | D8: glycopeptide antibiotic | E8: 639.66667 | F8: 225.66667 | G8: -1.6439 | H8: 0.0054321 | I8: geneset000713826 | J8: 43437.667 | K8: 10217.667 | L8: k__Bacteria | M8: p__Firmicutes | N8: c__Clostridia | O8: o__Clostridiales | P8: f__Lachnospiraceae | Q8: g__Lachnoclostridium | R8: s__Lachnoclostridium_sp._An138 | S8: 63667 | T8: 51260 | U8: 71284 | V8: 11536 | W8: 25880 | X8: 12271
A9: vanI | B9: 391.66667 | C9: 125.33333 | D9: glycopeptide antibiotic | E9: 639.66667 | F9: 225.66667 | G9: -1.6439 | H9: 0.0054321 | I9: geneset000727689 | J9: 111677.33 | K9: 33848.333 | L9: k__Bacteria | M9: p__Unclassified | N9: c__Unclassified | O9: o__Unclassified | P9: f__Unclassified | Q9: g__Unclassified | R9: s__bacterium_1xD42-67 | S9: 64890 | T9: 61298 | U9: 63082 | V9: 15587 | W9: 59600 | X9: 14788
A10: vanI | B10: 391.66667 | C10: 125.33333 | D10: glycopeptide antibiotic | E10: 639.66667 | F10: 225.66667 | G10: -1.6439 | H10: 0.0054321 | I10: geneset000730993 | J10: 101485.67 | K10: 36947 | L10: k__Bacteria | M10: p__Firmicutes | N10: c__Clostridia | O10: o__Clostridiales | P10: f__Lachnospiraceae | Q10: g__Acetatifactor | R10: s__Acetatifactor_muris | S10: 64890 | T10: 61298 | U10: 63082 | V10: 15587 | W10: 59600 | X10: 14788
A11: vanI | B11: 391.66667 | C11: 125.33333 | D11: glycopeptide antibiotic | E11: 639.66667 | F11: 225.66667 | G11: -1.6439 | H11: 0.0054321 | I11: geneset000740658 | J11: 3189.3333 | K11: 3365.6667 | L11: k__Bacteria | M11: p__Firmicutes | N11: c__Clostridia | O11: o__Clostridiales | P11: f__Clostridiales_Family_XIII._Incertae_Sedis | Q11: g__Unclassified | R11: s__Clostridiales_Family_XIII_bacterium | S11: 115697 | T11: 85831 | U11: 102929 | V11: 24281 | W11: 50643 | X11: 35917
A12: vanI | B12: 391.66667 | C12: 125.33333 | D12: glycopeptide antibiotic | E12: 639.66667 | F12: 225.66667 | G12: -1.6439 | H12: 0.0054321 | I12: geneset000892979 | J12: 62070.333 | K12: 16562.333 | L12: k__Bacteria | M12: p__Unclassified | N12: c__Unclassified | O12: o__Unclassified | P12: f__Unclassified | Q12: g__Unclassified | R12: s__bacterium_0.1xD8-82 | S12: 115697 | T12: 85831 | U12: 102929 | V12: 24281 | W12: 50643 | X12: 35917
A13: vanI | B13: 391.66667 | C13: 125.33333 | D13: glycopeptide antibiotic | E13: 639.66667 | F13: 225.66667 | G13: -1.6439 | H13: 0.0054321 | I13: geneset001177162 | J13: 63090 | K13: 29991.667 | L13: k__Bacteria | M13: p__Firmicutes | N13: c__Clostridia | O13: o__Clostridiales | P13: f__Lachnospiraceae | Q13: g__Unclassified | R13: s__Lachnospiraceae_bacterium_10-1 | S13: 333 | T13: 233 | U13: 180 | V13: 93 | W13: 131 | X13: 86
... A28: bcrA | B28: 10 | C28: 0 | D28: peptide antibiotic | E28: 49.333333 | F28: 54.666667 | G28: -4.3219 | H28: 0.0024128 | I28: geneset000340352 | J28: 9586.6667 | K28: 3419.6667 | L28: k__Bacteria | M28: p__Firmicutes | N28: c__Clostridia | O28: o__Clostridiales | P28: f__Lachnospiraceae | Q28: g__Roseburia | R28: s__Roseburia_intestinalis | S28: 8265 | T28: 11602 | U28: 8893 | V28: 2453 | W28: 5875 | X28: 1931

Sheet 5
B1: CK | C1: NPs | E1: Resistance | F1: CK | G1: NPs | I1: log2(FC) | J1: raw.pval | K1: GENE | N1: CK | O1: NPs
A2: vanI | B2: 391.66667 | C2: 125.33333 | D2: =LOG10(B2+C2) -> 2.7134905 | E2: glycopeptide antibiotic | F2: 639.66667 | G2: 225.66667 | H2: =LOG10(F2+G2) -> 2.9371834 | I2: -1.6439 | J2: 0.0054321 | K2: geneset000196490 | L2: f__Lachnospiraceae | M2: s__Lachnospiraceae_bacterium_3-1 | N2: 147890.67 | O2: 87928.333 | P2: =LOG10(N2+O2) -> 5.3725788 | Q2: 5.1699408 | R2: 4.9441288
A3: pp-flo | B3: 10 | C3: 0 | D3: =LOG10(B3+C3) -> 1 | E3: phenicol antibiotic | F3: 75 | G3: 9.3333333 | H3: =LOG10(F3+G3) -> 1.9259993 | I3: -3.8074 | J3: 0.036734 | K3: geneset000470980 | L3: f__Oscillospiraceae | M3: s__Oscillibacter_sp._1-3 | N3: 158596.33 | O3: 43682.667 | P3: =LOG10(N3+O3) -> 5.3059508 | Q3: 5.2002931 | R3: 4.6403091
A4: vanI | B4: 391.66667 | C4: 125.33333 | D4: =LOG10(B4+C4) -> 2.7134905 | E4: glycopeptide antibiotic | F4: 639.66667 | G4: 225.66667 | H4: =LOG10(F4+G4) -> 2.9371834 | I4: -1.6439 | J4: 0.0054321 | K4: geneset000727689 | L4: f__Unclassified | M4: s__bacterium_1xD42-67 | N4: 111677.33 | O4: 33848.333 | P4: =LOG10(N4+O4) -> 5.1629396 | Q4: 5.047965 | R4: 4.5295373
A5: vanI | B5: 391.66667 | C5: 125.33333 | D5: =LOG10(B5+C5) -> 2.7134905 | E5: glycopeptide antibiotic | F5: 639.66667 | G5: 225.66667 | H5: =LOG10(F5+G5) -> 2.9371834 | I5: -1.6439 | J5: 0.0054321 | K5: geneset000730993 | L5: f__Lachnospiraceae | M5: s__Acetatifactor_muris | N5: 101485.67 | O5: 36947 | P5: =LOG10(N5+O5) -> 5.1412386 | Q5: 5.0064047 | R5: 4.5675792
A6: vanI | B6: 391.66667 | C6: 125.33333 | D6: =LOG10(B6+C6) -> 2.7134905 | E6: glycopeptide antibiotic | F6: 639.66667 | G6: 225.66667 | H6: =LOG10(F6+G6) -> 2.9371834 | I6: -1.6439 | J6: 0.0054321 | K6: geneset001177162 | L6: f__Lachnospiraceae | M6: s__Lachnospiraceae_bacterium_10-1 | N6: 63090 | O6: 29991.667 | P6: =LOG10(N6+O6) -> 4.9688642 | Q6: 4.7999605 | R6: 4.4770006
A7: pp-flo | B7: 10 | C7: 0 | D7: =LOG10(B7+C7) -> 1 | E7: phenicol antibiotic | F7: 15 | G7: 3 | H7: =LOG10(F7+G7) -> 1.2552725 | I7: -3.8074 | J7: 0.036734 | K7: geneset000520075 | L7: f__Clostridiaceae | M7: s__Butyricicoccus_sp._1XD8-22 | N7: 68419 | O7: 22090.667 | P7: =LOG10(N7+O7) -> 4.956695 | Q7: 4.8351767 | R7: 4.3442088
A8: cipA | B8: 10 | C8: 0 | D8: =LOG10(B8+C8) -> 1 | E8: lincosamide antibiotic | F8: 15 | G8: 3 | H8: =LOG10(F8+G8) -> 1.2552725 | M8: s__Butyricicoccus_sp._1XD8-22
A9: cipA | B9: 10 | C9: 0 | D9: =LOG10(B9+C9) -> 1 | E9: pleuromutilin antibiotic | F9: 15 | G9: 3 | H9: =LOG10(F9+G9) -> 1.2552725 | M9: s__Butyricicoccus_sp._1XD8-22
A10: cipA | B10: 10 | C10: 0 | D10: =LOG10(B10+C10) -> 1 | E10: macrolide antibiotic | F10: 15 | G10: 3 | H10: =LOG10(F10+G10) -> 1.2552725 | M10: s__Butyricicoccus_sp._1XD8-22
A11: cipA | B11: 10 | C11: 0 | D11: =LOG10(B11+C11) -> 1 | E11: oxazolidinone antibiotic | F11: 15 | G11: 3 | H11: =LOG10(F11+G11) -> 1.2552725 | M11: s__Butyricicoccus_sp._1XD8-22
A12: cipA | B12: 10 | C12: 0 | D12: =LOG10(B12+C12) -> 1 | E12: streptogramin antibiotic | F12: 15 | G12: 3 | H12: =LOG10(F12+G12) -> 1.2552725 | M12: s__Butyricicoccus_sp._1XD8-22
A13: cipA | B13: 10 | C13: 0 | D13: =LOG10(B13+C13) -> 1 | E13: phenicol antibiotic | F13: 20.333333 | G13: 23.666667 | H13: =LOG10(F13+G13) -> 1.6434527 | I13: -3 | J13: 0.025218 | K13: geneset001056527 | L13: f__Eubacteriaceae | M13: s__Eubacterium_plexicaudatum | N13: 63845.333 | O13: 17431.333 | P13: =LOG10(N13+O13) -> 4.9099659 | Q13: 4.8051292 | R13: 4.2413306
A14: vanI | B14: 391.66667 | C14: 125.33333 | D14: =LOG10(B14+C14) -> 2.7134905 | E14: glycopeptide antibiotic | F14: 639.66667 | G14: 225.66667 | H14: =LOG10(F14+G14) -> 2.9371834 | I14: -1.6439 | J14: 0.0054321 | K14: geneset000892979 | L14: f__Unclassified | M14: s__bacterium_0.1xD8-82 | N14: 62070.333 | O14: 16562.333 | P14: =LOG10(N14+O14) -> 4.895603 | Q14: 4.7928841 | R14: 4.2191215
A15: bcrA | B15: 10 | C15: 0 | D15: =LOG10(B15+C15) -> 1 | E15: peptide antibiotic | F15: 49.333333 | G15: 54.666667 | H15: =LOG10(F15+G15) -> 2.0170333 | I15: -4.3219 | J15: 0.0024128 | K15: geneset000340352 | L15: f__Lachnospiraceae | M15: s__Roseburia_intestinalis | N15: 9586.6667 | O15: 3419.6667 | P15: =LOG10(N15+O15) -> 4.1141549 | Q15: 3.9816676 | R15: 3.5339838
A16: vanI | B16: 391.66667 | C16: 125.33333 | D16: =LOG10(B16+C16) -> 2.7134905 | E16: glycopeptide antibiotic | F16: 639.66667 | G16: 225.66667 | H16: =LOG10(F16+G16) -> 2.9371834 | I16: -1.6439 | J16: 0.0054321 | K16: geneset000740658 | L16: f__Clostridiales_Family_XIII._Incertae_Sedis | M16: s__Clostridiales_Family_XIII_bacterium | N16: 3189.3333 | O16: 3365.6667 | P16: =LOG10(N16+O16) -> 3.8165727 | Q16: 3.5036999 | R16: 3.5270711
A17: SAT-4 | B17: 21.333333 | C17: 6.6666667 | D17: =LOG10(B17+C17) -> 1.447158 | E17: nucleoside antibiotic | F17: 21.333333 | G17: 6.6666667 | H17: =LOG10(F17+G17) -> 1.447158 | I17: -1.6781 | J17: 0.016997 | K17: geneset001461830 | L17: f__Succinivibrionaceae | M17: s__Succinivibrio_dextrinosolvens | N17: 361 | O17: 144.33333 | P17: =LOG10(N17+O17) -> 2.7035779 | Q17: 2.5575072 | R17: 2.1593666
A18: Listeria monocytogenes mprF | B18: 4 | C18: 0.33333333 | D18: =LOG10(B18+C18) -> 0.6368221 | E18: peptide antibiotic | F18: 49.333333 | G18: 54.666667 | H18: =LOG10(F18+G18) -> 2.0170333 | I18: -2.585 | J18: 0.0045624 | K18: geneset001044074 | L18: f__Desulfovibrionaceae | M18: s__Desulfovibrio_africanus | N18: 123 | O18: 11 | P18: =LOG10(N18+O18) -> 2.1271048 | Q18: 2.0899051 | R18: 1.0413927
A19: Listeria monocytogenes mprF | B19: 4 | C19: 0.33333333 | D19: =LOG10(B19+C19) -> 0.6368221 | E19: peptide antibiotic | F19: 49.333333 | G19: 54.666667 | H19: =LOG10(F19+G19) -> 2.0170333 | I19: -2.585 | J19: 0.0045624 | K19: geneset001638141 | L19: f__Paenibacillaceae | M19: s__Paenibacillus_kribbensis | N19: 62.666667 | O19: 11 | P19: =LOG10(N19+O19) -> 1.867271 | Q19: 1.7970366 | R19: 1.0413927
A20: tetW | B20: 33 | C20: 11.333333 | D20: =LOG10(B20+C20) -> 1.6467304 | E20: tetracycline antibiotic | F20: 1616 | G20: 871 | H20: =LOG10(F20+G20) -> 3.3956758 | I20: -1.5419 | J20: 0.039823 | K20: geneset001182843 | L20: f__Bifidobacteriaceae | M20: s__Bifidobacterium_pullorum | N20: 46.333333 | O20: 22.666667 | P20: =LOG10(N20+O20) -> 1.8388491 | Q20: 1.6658935 | R20: 1.3553877
A21: clbB | B21: 5 | C21: 1 | D21: =LOG10(B21+C21) -> 0.77815125 | E21: lincosamide antibiotic | F21: 4 | G21: 4.5 | H21: =LOG10(F21+G21) -> 0.92941893 | I21: -3.2327 | J21: 0.042778 | K21: geneset001090838 | L21: f__Clostridiaceae | M21: s__Clostridium_algidicarnis | N21: 22 | O21: 18 | P21: =LOG10(N21+O21) -> 1.60206 | Q21: 1.3424227 | R21: 1.2552725
A22: clbB | B22: 5 | C22: 1 | D22: =LOG10(B22+C22) -> 0.77815125 | E22: pleuromutilin antibiotic | F22: 4 | G22: 4.5 | H22: =LOG10(F22+G22) -> 0.92941893 | M22: s__Clostridium_algidicarnis
A23: clbB | B23: 5 | C23: 1 | D23: =LOG10(B23+C23) -> 0.77815125 | E23: macrolide antibiotic | F23: 4 | G23: 4.5 | H23: =LOG10(F23+G23) -> 0.92941893 | M23: s__Clostridium_algidicarnis
A24: clbB | B24: 5 | C24: 1 | D24: =LOG10(B24+C24) -> 0.77815125 | E24: oxazolidinone antibiotic | F24: 4 | G24: 4.5 | H24: =LOG10(F24+G24) -> 0.92941893 | M24: s__Clostridium_algidicarnis
A25: clbB | B25: 5 | C25: 1 | D25: =LOG10(B25+C25) -> 0.77815125 | E25: streptogramin antibiotic | F25: 4 | G25: 4.5 | H25: =LOG10(F25+G25) -> 0.92941893 | M25: s__Clostridium_algidicarnis
A26: clbB | B26: 5 | C26: 1 | D26: =LOG10(B26+C26) -> 0.77815125 | E26: phenicol antibiotic | F26: 4 | G26: 4.5 | H26: =LOG10(F26+G26) -> 0.92941893
